(dp1
S'output'
p2
S"<type 'exceptions.SyntaxError'> Field clientes_nome does not belong to the table"
p3
sS'layer'
p4
S'/home/python/web2pyLojinha/applications/lojinha/controllers/importMysql.py'
p5
sS'code'
p6
S'def produtos(): \n    path = request.folder+"static/mysqlImport/produtos.csv"\n    f = file(path,\'r\')\n\n    # linha = f.readline().split(\',\')\n    \n    for l in f.readlines():\n    \tlinha = l.split(\',\')\n    \tdb.produtos.insert(codigo_produto=linha[1],nome_produto=linha[2],preco_produto_lojinha=linha[5],dataGravado=linha[4])\n    \n    f.close()\n\n    return dict()\n\ndef clientes(): \n    path = request.folder+"static/mysqlImport/clientes_lojinha.csv"\n    f = file(path,\'r\')\n\n    # linha = f.readline().split(\',\')\n\n    for l in f.readlines():\n    \tlinha = l.split(\',\')\n        celular = linha[9].split(\' - \')\n    \tcel = "%s"%celular[0]\n    \toperadora = "%s"%celular[1]\n    \t# db.clientes.insert(clientes_nome=linha[1],clientes_celular=cel,clientes_operadora=operadora,clientes_email=linha[10],clientes_dataGravado=linha[14])\n    \tprint linha[1]\n    \t# db.clientes.insert(clientes_nome=linha[1])\n    \n    db.clientes.insert(clientes_nome="jose")\t\n\n    f.close()\n\n    return dict()    \nresponse._vars=response._caller(clientes)\n'
p7
sS'snapshot'
p8
(dp9
sS'traceback'
p10
S'Traceback (most recent call last):\n  File "/home/python/web2pyLojinha/gluon/restricted.py", line 227, in restricted\n    exec ccode in environment\n  File "/home/python/web2pyLojinha/applications/lojinha/controllers/importMysql.py", line 35, in <module>\n  File "/home/python/web2pyLojinha/gluon/globals.py", line 412, in <lambda>\n    self._caller = lambda f: f()\n  File "/home/python/web2pyLojinha/applications/lojinha/controllers/importMysql.py", line 30, in clientes\n    db.clientes.insert(clientes_nome="jose")\n  File "/home/python/web2pyLojinha/gluon/packages/dal/pydal/objects.py", line 712, in insert\n    ret = self._db._adapter.insert(self, self._listify(fields))\n  File "/home/python/web2pyLojinha/gluon/packages/dal/pydal/objects.py", line 629, in _listify\n    \'Field %s does not belong to the table\' % name)\nSyntaxError: Field clientes_nome does not belong to the table\n'
p11
s.